I'm sorry, but an uncaught exception occurred.

While running game code:
  File "game/script.rpy", line 29, in script
    i "Does everyone really arrive after 10…?"
KeyError: 'povname'

-- Full Traceback ------------------------------------------------------------

Full traceback:
  File "game/script.rpy", line 29, in script
    i "Does everyone really arrive after 10…?"
  File "/Applications/renpy-6.99.8-sdk/renpy/ast.py", line 603, in execute
    renpy.exports.say(who, what, interact=self.interact)
  File "/Applications/renpy-6.99.8-sdk/renpy/exports.py", line 1121, in say
    who(what, interact=interact)
  File "/Applications/renpy-6.99.8-sdk/renpy/character.py", line 806, in __call__
    who = who_pattern.replace("[who]", sub(who))
  File "/Applications/renpy-6.99.8-sdk/renpy/character.py", line 801, in sub
    return renpy.substitutions.substitute(s, scope=scope, force=force, translate=translate)[0]
  File "/Applications/renpy-6.99.8-sdk/renpy/substitutions.py", line 229, in substitute
    s = formatter.vformat(s, (), kwargs)
  File "/home/tom/ab/x64lucid-deps/install/lib/python2.7/string.py", line 563, in vformat
  File "/home/tom/ab/x64lucid-deps/install/lib/python2.7/string.py", line 585, in _vformat
  File "/home/tom/ab/x64lucid-deps/install/lib/python2.7/string.py", line 646, in get_field
  File "/home/tom/ab/x64lucid-deps/install/lib/python2.7/string.py", line 605, in get_value
KeyError: 'povname'

Darwin-15.2.0-x86_64-i386-64bit
Ren'Py 6.99.8.959
Game Dev Intern 0.0
